2025-09-25 07:57:48,457 [INFO] - ============================================================
2025-09-25 07:57:48,457 [INFO] - INICIANDO NOVA EXECUÇÃO DA RPA
2025-09-25 07:57:48,457 [INFO] - ============================================================
2025-09-25 07:57:48,564 [INFO] - FASE 1: LOGIN E CONFIGURAÇÃO DA SESSÃO
2025-09-25 07:57:51,369 [CRITICAL] - Ocorreu uma falha inesperada na automação.
Traceback (most recent call last):
  File "/Users/rildonpimentelpereira/GitHub/OneNotify/main.py", line 49, in main
    browser, context, browser_process_ref, page = realizar_login_automatico(playwright)
  File "/Users/rildonpimentelpereira/GitHub/OneNotify/autologin.py", line 76, in realizar_login_automatico
    portal_page.locator("#aPaginaInicial").wait_for(state="visible", timeout=90000)
  File "/Users/rildonpimentelpereira/GitHub/OneNotify/venv/lib/python3.9/site-packages/playwright/sync_api/_generated.py", line 17975, in wait_for
    self._sync(self._impl_obj.wait_for(timeout=timeout, state=state))
  File "/Users/rildonpimentelpereira/GitHub/OneNotify/venv/lib/python3.9/site-packages/playwright/_impl/_sync_base.py", line 115, in _sync
    return task.result()
  File "/Users/rildonpimentelpereira/GitHub/OneNotify/venv/lib/python3.9/site-packages/playwright/_impl/_locator.py", line 692, in wait_for
    await self._frame.wait_for_selector(
  File "/Users/rildonpimentelpereira/GitHub/OneNotify/venv/lib/python3.9/site-packages/playwright/_impl/_frame.py", line 369, in wait_for_selector
    await self._channel.send(
  File "/Users/rildonpimentelpereira/GitHub/OneNotify/venv/lib/python3.9/site-packages/playwright/_impl/_connection.py", line 69, in send
    return await self._connection.wrap_api_call(
  File "/Users/rildonpimentelpereira/GitHub/OneNotify/venv/lib/python3.9/site-packages/playwright/_impl/_connection.py", line 558, in wrap_api_call
    raise rewrite_error(error, f"{parsed_st['apiName']}: {error}") from None
playwright._impl._errors.TargetClosedError: Locator.wait_for: Target page, context or browser has been closed
2025-09-25 07:57:51,369 [INFO] - Finalizando a automação e fechando o navegador.
2025-09-25 07:57:51,369 [ERROR] - ERRO ao salvar log de execução: table logs_execucao has no column named andamentos
Traceback (most recent call last):
  File "/Users/rildonpimentelpereira/GitHub/OneNotify/database.py", line 160, in salvar_log_execucao
    cursor.execute(query, list(log_data.values()))
sqlite3.OperationalError: table logs_execucao has no column named andamentos
2025-09-25 07:57:51,370 [INFO] - 
============================================================
RESUMO FINAL DA EXECUÇÃO (25/09/2025 07:57:51)
============================================================
- Duração Total: 2.81 segundos
- Notificações Salvas: 0
- NPJs com Sucesso: 0
- NPJs com Falha: 0
============================================================

